Workbook

Sheet ALMACENES
A1: NOMBRE | B1: CODIGO
A2: 7 - ALMACEN CENTTRAL | B2: 7
A3: 8 - ALMACEN PRUEBA | B3: 8

Sheet MARCAS
A1: NOMBRE | B1: CODIGO
A2: 9 - PAVCO | B2: 9
A3: 13 - TREBOL | B3: 13
A4: 14 - TOOLCRAFT | B4: 14
A5: 15 - GENERICO | B5: 15
A6: 16 - KBA ELECTRICS | B6: 16
A7: 17 - SANDFLEX | B7: 17
A8: 18 - ACEROS AREQUIPA | B8: 18
A9: 19 - ASAKI | B9: 19
A10: 20 - OATEY | B10: 20
A11: 21 - SAPOLIO | B11: 21
A12: 22 - TEKNO | B12: 22
A13: 23 - ANYPSA | B13: 23
... A36: 46 - TRAMONTINA | B36: 46

Sheet UNIDADES
A1: NOMBRE | B1: CODIGO
A2: 1 - UNIDADES | B2: 1
A3: 2 - KILOGRAMO | B3: 2
A4: 3 - BALDE | B4: 3
A5: 4 - BOLSA | B5: 4
A6: 5 - BOTELLAS | B6: 5
A7: 6 - CAJA | B7: 6
A8: 7 - CARTONES | B8: 7
A9: 8 - CILINDRO | B9: 8
A10: 9 - CONOS | B10: 9
A11: 10 - GRAMO | B11: 10
A12: 11 - JUEGO | B12: 11
A13: 12 - KILOMETRO | B13: 12
... A21: 20 - UNIDAD SERVICIOS | B21: 20

Sheet CATEGORIAS
A1: NOMBRE | B1: CODIGO
A2: 15 - Vlvulas de PVC | B2: 15
A3: 16 - GRIFERIA TREBOL | B3: 16
A4: 17 - Aergrafos | B4: 17
A5: 18 - VARIOS | B5: 18
A6: 19 - Tableros Elctricos | B6: 19
A7: 20 - PRODUCTOS PVC | B7: 20
A8: 21 - Accesorios para taladros | B8: 21
A9: 22 - HOJA DE SIERRA | B9: 22
A10: 23 - PEGAMENTO | B10: 23
A11: 24 - ESCOBILLA DE COPA | B11: 24
A12: 25 - PEGAMENTE PARA PVC | B12: 25
A13: 26 - LIMPIEZA | B13: 26
... A28: 41 - PARAPENTE | B28: 41

Sheet TIPO_ARTICULOS
A1: NOMBRE | B1: CODIGO
A2: 1 - PRODUCTO | B2: 1
A3: 2 - SERVICIO | B3: 2

Sheet PRODUCTOS
A1: ALMACENES | C1: MARCAS | E1: UNIDADES | G1: CATEGORIAS | I1: TIPO_ARTICULOS | K1: NOMBRE PRODUCTO | L1: PRECIO COMPRA | M1: PRECIO VENTA | N1: PRECIO MAYOR | O1: PRECIO ESPECIAL | P1: STOCK ACTUAL | Q1: STOCK MÍNIMO | R1: SERIE | S1: CÓDIGO DE BARRAS | T1: TIPO IGV
A2: 7 - ALMACEN CENTTRAL | B2: =VLOOKUP(A2,ALMACENES!A2:B3,2,FALSE) -> 7 | C2: 15 - GENERICO | D2: =VLOOKUP(C2,MARCAS!A2:B36,2,FALSE) -> 15 | E2: 1 - UNIDADES | F2: =VLOOKUP(E2,UNIDADES!A2:B21,2,FALSE) -> 1 | G2: 18 - VARIOS | H2: =VLOOKUP(G2,CATEGORIAS!A2:B28,2,FALSE) -> 18 | I2: 1 - PRODUCTO | J2: =VLOOKUP(I2,TIPO_ARTICULOS!A2:B3,2,FALSE) -> 1 | K2: CEMENTO ANDINO | L2: 20 | M2: 30 | N2: 30 | O2: 30 | P2: 20 | Q2: 1 | R2: 352121017478745 | S2: CEME123
B3: =VLOOKUP(A3,ALMACENES!A2:B3,2,FALSE) -> #N/A | D3: =VLOOKUP(C3,MARCAS!A2:B36,2,FALSE) -> #N/A | F3: =VLOOKUP(E3,UNIDADES!A2:B21,2,FALSE) -> #N/A | H3: =VLOOKUP(G3,CATEGORIAS!A2:B28,2,FALSE) -> #N/A | J3: =VLOOKUP(I3,TIPO_ARTICULOS!A2:B3,2,FALSE) -> #N/A
B4: =VLOOKUP(A4,ALMACENES!A2:B3,2,FALSE) -> #N/A | D4: =VLOOKUP(C4,MARCAS!A2:B36,2,FALSE) -> #N/A | F4: =VLOOKUP(E4,UNIDADES!A2:B21,2,FALSE) -> #N/A | H4: =VLOOKUP(G4,CATEGORIAS!A2:B28,2,FALSE) -> #N/A | J4: =VLOOKUP(I4,TIPO_ARTICULOS!A2:B3,2,FALSE) -> #N/A
B5: =VLOOKUP(A5,ALMACENES!A2:B3,2,FALSE) -> #N/A | D5: =VLOOKUP(C5,MARCAS!A2:B36,2,FALSE) -> #N/A | F5: =VLOOKUP(E5,UNIDADES!A2:B21,2,FALSE) -> #N/A | H5: =VLOOKUP(G5,CATEGORIAS!A2:B28,2,FALSE) -> #N/A | J5: =VLOOKUP(I5,TIPO_ARTICULOS!A2:B3,2,FALSE) -> #N/A
B6: =VLOOKUP(A6,ALMACENES!A2:B3,2,FALSE) -> #N/A | D6: =VLOOKUP(C6,MARCAS!A2:B36,2,FALSE) -> #N/A | F6: =VLOOKUP(E6,UNIDADES!A2:B21,2,FALSE) -> #N/A | H6: =VLOOKUP(G6,CATEGORIAS!A2:B28,2,FALSE) -> #N/A | J6: =VLOOKUP(I6,TIPO_ARTICULOS!A2:B3,2,FALSE) -> #N/A
B7: =VLOOKUP(A7,ALMACENES!A2:B3,2,FALSE) -> #N/A | D7: =VLOOKUP(C7,MARCAS!A2:B36,2,FALSE) -> #N/A | F7: =VLOOKUP(E7,UNIDADES!A2:B21,2,FALSE) -> #N/A | H7: =VLOOKUP(G7,CATEGORIAS!A2:B28,2,FALSE) -> #N/A | J7: =VLOOKUP(I7,TIPO_ARTICULOS!A2:B3,2,FALSE) -> #N/A
B8: =VLOOKUP(A8,ALMACENES!A2:B3,2,FALSE) -> #N/A | D8: =VLOOKUP(C8,MARCAS!A2:B36,2,FALSE) -> #N/A | F8: =VLOOKUP(E8,UNIDADES!A2:B21,2,FALSE) -> #N/A | H8: =VLOOKUP(G8,CATEGORIAS!A2:B28,2,FALSE) -> #N/A | J8: =VLOOKUP(I8,TIPO_ARTICULOS!A2:B3,2,FALSE) -> #N/A
B9: =VLOOKUP(A9,ALMACENES!A2:B3,2,FALSE) -> #N/A | D9: =VLOOKUP(C9,MARCAS!A2:B36,2,FALSE) -> #N/A | F9: =VLOOKUP(E9,UNIDADES!A2:B21,2,FALSE) -> #N/A | H9: =VLOOKUP(G9,CATEGORIAS!A2:B28,2,FALSE) -> #N/A | J9: =VLOOKUP(I9,TIPO_ARTICULOS!A2:B3,2,FALSE) -> #N/A
B10: =VLOOKUP(A10,ALMACENES!A2:B3,2,FALSE) -> #N/A | D10: =VLOOKUP(C10,MARCAS!A2:B36,2,FALSE) -> #N/A | F10: =VLOOKUP(E10,UNIDADES!A2:B21,2,FALSE) -> #N/A | H10: =VLOOKUP(G10,CATEGORIAS!A2:B28,2,FALSE) -> #N/A | J10: =VLOOKUP(I10,TIPO_ARTICULOS!A2:B3,2,FALSE) -> #N/A
B11: =VLOOKUP(A11,ALMACENES!A2:B3,2,FALSE) -> #N/A | D11: =VLOOKUP(C11,MARCAS!A2:B36,2,FALSE) -> #N/A | F11: =VLOOKUP(E11,UNIDADES!A2:B21,2,FALSE) -> #N/A | H11: =VLOOKUP(G11,CATEGORIAS!A2:B28,2,FALSE) -> #N/A | J11: =VLOOKUP(I11,TIPO_ARTICULOS!A2:B3,2,FALSE) -> #N/A
B12: =VLOOKUP(A12,ALMACENES!A2:B3,2,FALSE) -> #N/A | D12: =VLOOKUP(C12,MARCAS!A2:B36,2,FALSE) -> #N/A | F12: =VLOOKUP(E12,UNIDADES!A2:B21,2,FALSE) -> #N/A | H12: =VLOOKUP(G12,CATEGORIAS!A2:B28,2,FALSE) -> #N/A | J12: =VLOOKUP(I12,TIPO_ARTICULOS!A2:B3,2,FALSE) -> #N/A
B13: =VLOOKUP(A13,ALMACENES!A2:B3,2,FALSE) -> #N/A | D13: =VLOOKUP(C13,MARCAS!A2:B36,2,FALSE) -> #N/A | F13: =VLOOKUP(E13,UNIDADES!A2:B21,2,FALSE) -> #N/A | H13: =VLOOKUP(G13,CATEGORIAS!A2:B28,2,FALSE) -> #N/A | J13: =VLOOKUP(I13,TIPO_ARTICULOS!A2:B3,2,FALSE) -> #N/A
B14: =VLOOKUP(A14,ALMACENES!A2:B3,2,FALSE) -> #N/A | D14: =VLOOKUP(C14,MARCAS!A2:B36,2,FALSE) -> #N/A | F14: =VLOOKUP(E14,UNIDADES!A2:B21,2,FALSE) -> #N/A | H14: =VLOOKUP(G14,CATEGORIAS!A2:B28,2,FALSE) -> #N/A | J14: =VLOOKUP(I14,TIPO_ARTICULOS!A2:B3,2,FALSE) -> #N/A
B15: =VLOOKUP(A15,ALMACENES!A2:B3,2,FALSE) -> #N/A | D15: =VLOOKUP(C15,MARCAS!A2:B36,2,FALSE) -> #N/A | F15: =VLOOKUP(E15,UNIDADES!A2:B21,2,FALSE) -> #N/A | H15: =VLOOKUP(G15,CATEGORIAS!A2:B28,2,FALSE) -> #N/A | J15: =VLOOKUP(I15,TIPO_ARTICULOS!A2:B3,2,FALSE) -> #N/A
B16: =VLOOKUP(A16,ALMACENES!A2:B3,2,FALSE) -> #N/A | D16: =VLOOKUP(C16,MARCAS!A2:B36,2,FALSE) -> #N/A | F16: =VLOOKUP(E16,UNIDADES!A2:B21,2,FALSE) -> #N/A | H16: =VLOOKUP(G16,CATEGORIAS!A2:B28,2,FALSE) -> #N/A | J16: =VLOOKUP(I16,TIPO_ARTICULOS!A2:B3,2,FALSE) -> #N/A
B17: =VLOOKUP(A17,ALMACENES!A2:B3,2,FALSE) -> #N/A | D17: =VLOOKUP(C17,MARCAS!A2:B36,2,FALSE) -> #N/A | F17: =VLOOKUP(E17,UNIDADES!A2:B21,2,FALSE) -> #N/A | H17: =VLOOKUP(G17,CATEGORIAS!A2:B28,2,FALSE) -> #N/A | J17: =VLOOKUP(I17,TIPO_ARTICULOS!A2:B3,2,FALSE) -> #N/A
B18: =VLOOKUP(A18,ALMACENES!A2:B3,2,FALSE) -> #N/A | D18: =VLOOKUP(C18,MARCAS!A2:B36,2,FALSE) -> #N/A | F18: =VLOOKUP(E18,UNIDADES!A2:B21,2,FALSE) -> #N/A | H18: =VLOOKUP(G18,CATEGORIAS!A2:B28,2,FALSE) -> #N/A | J18: =VLOOKUP(I18,TIPO_ARTICULOS!A2:B3,2,FALSE) -> #N/A
B19: =VLOOKUP(A19,ALMACENES!A2:B3,2,FALSE) -> #N/A | D19: =VLOOKUP(C19,MARCAS!A2:B36,2,FALSE) -> #N/A | F19: =VLOOKUP(E19,UNIDADES!A2:B21,2,FALSE) -> #N/A | H19: =VLOOKUP(G19,CATEGORIAS!A2:B28,2,FALSE) -> #N/A | J19: =VLOOKUP(I19,TIPO_ARTICULOS!A2:B3,2,FALSE) -> #N/A
B20: =VLOOKUP(A20,ALMACENES!A2:B3,2,FALSE) -> #N/A | D20: =VLOOKUP(C20,MARCAS!A2:B36,2,FALSE) -> #N/A | F20: =VLOOKUP(E20,UNIDADES!A2:B21,2,FALSE) -> #N/A | H20: =VLOOKUP(G20,CATEGORIAS!A2:B28,2,FALSE) -> #N/A | J20: =VLOOKUP(I20,TIPO_ARTICULOS!A2:B3,2,FALSE) -> #N/A
B21: =VLOOKUP(A21,ALMACENES!A2:B3,2,FALSE) -> #N/A | D21: =VLOOKUP(C21,MARCAS!A2:B36,2,FALSE) -> #N/A | F21: =VLOOKUP(E21,UNIDADES!A2:B21,2,FALSE) -> #N/A | H21: =VLOOKUP(G21,CATEGORIAS!A2:B28,2,FALSE) -> #N/A | J21: =VLOOKUP(I21,TIPO_ARTICULOS!A2:B3,2,FALSE) -> #N/A
B22: =VLOOKUP(A22,ALMACENES!A2:B3,2,FALSE) -> #N/A | D22: =VLOOKUP(C22,MARCAS!A2:B36,2,FALSE) -> #N/A | F22: =VLOOKUP(E22,UNIDADES!A2:B21,2,FALSE) -> #N/A | H22: =VLOOKUP(G22,CATEGORIAS!A2:B28,2,FALSE) -> #N/A | J22: =VLOOKUP(I22,TIPO_ARTICULOS!A2:B3,2,FALSE) -> #N/A
B23: =VLOOKUP(A23,ALMACENES!A2:B3,2,FALSE) -> #N/A | D23: =VLOOKUP(C23,MARCAS!A2:B36,2,FALSE) -> #N/A | F23: =VLOOKUP(E23,UNIDADES!A2:B21,2,FALSE) -> #N/A | H23: =VLOOKUP(G23,CATEGORIAS!A2:B28,2,FALSE) -> #N/A | J23: =VLOOKUP(I23,TIPO_ARTICULOS!A2:B3,2,FALSE) -> #N/A
B24: =VLOOKUP(A24,ALMACENES!A2:B3,2,FALSE) -> #N/A | D24: =VLOOKUP(C24,MARCAS!A2:B36,2,FALSE) -> #N/A | F24: =VLOOKUP(E24,UNIDADES!A2:B21,2,FALSE) -> #N/A | H24: =VLOOKUP(G24,CATEGORIAS!A2:B28,2,FALSE) -> #N/A | J24: =VLOOKUP(I24,TIPO_ARTICULOS!A2:B3,2,FALSE) -> #N/A
B25: =VLOOKUP(A25,ALMACENES!A2:B3,2,FALSE) -> #N/A | D25: =VLOOKUP(C25,MARCAS!A2:B36,2,FALSE) -> #N/A | F25: =VLOOKUP(E25,UNIDADES!A2:B21,2,FALSE) -> #N/A | H25: =VLOOKUP(G25,CATEGORIAS!A2:B28,2,FALSE) -> #N/A | J25: =VLOOKUP(I25,TIPO_ARTICULOS!A2:B3,2,FALSE) -> #N/A
B26: =VLOOKUP(A26,ALMACENES!A2:B3,2,FALSE) -> #N/A | D26: =VLOOKUP(C26,MARCAS!A2:B36,2,FALSE) -> #N/A | F26: =VLOOKUP(E26,UNIDADES!A2:B21,2,FALSE) -> #N/A | H26: =VLOOKUP(G26,CATEGORIAS!A2:B28,2,FALSE) -> #N/A | J26: =VLOOKUP(I26,TIPO_ARTICULOS!A2:B3,2,FALSE) -> #N/A
B27: =VLOOKUP(A27,ALMACENES!A2:B3,2,FALSE) -> #N/A | D27: =VLOOKUP(C27,MARCAS!A2:B36,2,FALSE) -> #N/A | F27: =VLOOKUP(E27,UNIDADES!A2:B21,2,FALSE) -> #N/A | H27: =VLOOKUP(G27,CATEGORIAS!A2:B28,2,FALSE) -> #N/A | J27: =VLOOKUP(I27,TIPO_ARTICULOS!A2:B3,2,FALSE) -> #N/A
B28: =VLOOKUP(A28,ALMACENES!A2:B3,2,FALSE) -> #N/A | D28: =VLOOKUP(C28,MARCAS!A2:B36,2,FALSE) -> #N/A | F28: =VLOOKUP(E28,UNIDADES!A2:B21,2,FALSE) -> #N/A | H28: =VLOOKUP(G28,CATEGORIAS!A2:B28,2,FALSE) -> #N/A | J28: =VLOOKUP(I28,TIPO_ARTICULOS!A2:B3,2,FALSE) -> #N/A
B29: =VLOOKUP(A29,ALMACENES!A2:B3,2,FALSE) -> #N/A | D29: =VLOOKUP(C29,MARCAS!A2:B36,2,FALSE) -> #N/A | F29: =VLOOKUP(E29,UNIDADES!A2:B21,2,FALSE) -> #N/A | H29: =VLOOKUP(G29,CATEGORIAS!A2:B28,2,FALSE) -> #N/A | J29: =VLOOKUP(I29,TIPO_ARTICULOS!A2:B3,2,FALSE) -> #N/A
B30: =VLOOKUP(A30,ALMACENES!A2:B3,2,FALSE) -> #N/A | D30: =VLOOKUP(C30,MARCAS!A2:B36,2,FALSE) -> #N/A | F30: =VLOOKUP(E30,UNIDADES!A2:B21,2,FALSE) -> #N/A | H30: =VLOOKUP(G30,CATEGORIAS!A2:B28,2,FALSE) -> #N/A | J30: =VLOOKUP(I30,TIPO_ARTICULOS!A2:B3,2,FALSE) -> #N/A
B31: =VLOOKUP(A31,ALMACENES!A2:B3,2,FALSE) -> #N/A | D31: =VLOOKUP(C31,MARCAS!A2:B36,2,FALSE) -> #N/A | F31: =VLOOKUP(E31,UNIDADES!A2:B21,2,FALSE) -> #N/A | H31: =VLOOKUP(G31,CATEGORIAS!A2:B28,2,FALSE) -> #N/A | J31: =VLOOKUP(I31,TIPO_ARTICULOS!A2:B3,2,FALSE) -> #N/A
B32: =VLOOKUP(A32,ALMACENES!A2:B3,2,FALSE) -> #N/A | D32: =VLOOKUP(C32,MARCAS!A2:B36,2,FALSE) -> #N/A | F32: =VLOOKUP(E32,UNIDADES!A2:B21,2,FALSE) -> #N/A | H32: =VLOOKUP(G32,CATEGORIAS!A2:B28,2,FALSE) -> #N/A | J32: =VLOOKUP(I32,TIPO_ARTICULOS!A2:B3,2,FALSE) -> #N/A
B33: =VLOOKUP(A33,ALMACENES!A2:B3,2,FALSE) -> #N/A | D33: =VLOOKUP(C33,MARCAS!A2:B36,2,FALSE) -> #N/A | F33: =VLOOKUP(E33,UNIDADES!A2:B21,2,FALSE) -> #N/A | H33: =VLOOKUP(G33,CATEGORIAS!A2:B28,2,FALSE) -> #N/A | J33: =VLOOKUP(I33,TIPO_ARTICULOS!A2:B3,2,FALSE) -> #N/A
B34: =VLOOKUP(A34,ALMACENES!A2:B3,2,FALSE) -> #N/A | D34: =VLOOKUP(C34,MARCAS!A2:B36,2,FALSE) -> #N/A | F34: =VLOOKUP(E34,UNIDADES!A2:B21,2,FALSE) -> #N/A | H34: =VLOOKUP(G34,CATEGORIAS!A2:B28,2,FALSE) -> #N/A | J34: =VLOOKUP(I34,TIPO_ARTICULOS!A2:B3,2,FALSE) -> #N/A
B35: =VLOOKUP(A35,ALMACENES!A2:B3,2,FALSE) -> #N/A | D35: =VLOOKUP(C35,MARCAS!A2:B36,2,FALSE) -> #N/A | F35: =VLOOKUP(E35,UNIDADES!A2:B21,2,FALSE) -> #N/A | H35: =VLOOKUP(G35,CATEGORIAS!A2:B28,2,FALSE) -> #N/A | J35: =VLOOKUP(I35,TIPO_ARTICULOS!A2:B3,2,FALSE) -> #N/A
B36: =VLOOKUP(A36,ALMACENES!A2:B3,2,FALSE) -> #N/A | D36: =VLOOKUP(C36,MARCAS!A2:B36,2,FALSE) -> #N/A | F36: =VLOOKUP(E36,UNIDADES!A2:B21,2,FALSE) -> #N/A | H36: =VLOOKUP(G36,CATEGORIAS!A2:B28,2,FALSE) -> #N/A | J36: =VLOOKUP(I36,TIPO_ARTICULOS!A2:B3,2,FALSE) -> #N/A
B37: =VLOOKUP(A37,ALMACENES!A2:B3,2,FALSE) -> #N/A | D37: =VLOOKUP(C37,MARCAS!A2:B36,2,FALSE) -> #N/A | F37: =VLOOKUP(E37,UNIDADES!A2:B21,2,FALSE) -> #N/A | H37: =VLOOKUP(G37,CATEGORIAS!A2:B28,2,FALSE) -> #N/A | J37: =VLOOKUP(I37,TIPO_ARTICULOS!A2:B3,2,FALSE) -> #N/A
B38: =VLOOKUP(A38,ALMACENES!A2:B3,2,FALSE) -> #N/A | D38: =VLOOKUP(C38,MARCAS!A2:B36,2,FALSE) -> #N/A | F38: =VLOOKUP(E38,UNIDADES!A2:B21,2,FALSE) -> #N/A | H38: =VLOOKUP(G38,CATEGORIAS!A2:B28,2,FALSE) -> #N/A | J38: =VLOOKUP(I38,TIPO_ARTICULOS!A2:B3,2,FALSE) -> #N/A
B39: =VLOOKUP(A39,ALMACENES!A2:B3,2,FALSE) -> #N/A | D39: =VLOOKUP(C39,MARCAS!A2:B36,2,FALSE) -> #N/A | F39: =VLOOKUP(E39,UNIDADES!A2:B21,2,FALSE) -> #N/A | H39: =VLOOKUP(G39,CATEGORIAS!A2:B28,2,FALSE) -> #N/A | J39: =VLOOKUP(I39,TIPO_ARTICULOS!A2:B3,2,FALSE) -> #N/A
B40: =VLOOKUP(A40,ALMACENES!A2:B3,2,FALSE) -> #N/A | D40: =VLOOKUP(C40,MARCAS!A2:B36,2,FALSE) -> #N/A | F40: =VLOOKUP(E40,UNIDADES!A2:B21,2,FALSE) -> #N/A | H40: =VLOOKUP(G40,CATEGORIAS!A2:B28,2,FALSE) -> #N/A | J40: =VLOOKUP(I40,TIPO_ARTICULOS!A2:B3,2,FALSE) -> #N/A
...
