Workbook

Sheet ALMACEN
A1: NOMBRE | B1: CODIGO
A2: ALMACEN CENTRAL - 1 | B2: 1
A3: ALMACEN VENTAS - 2 | B3: 2

Sheet MARCA
A1: NOMBRE | B1: CODIGO
A2: GENERICOS - 1 | B2: 1

Sheet UNIDAD
A1: NOMBRE | B1: CODIGO
A2: BALDE - 3 | B2: 3
A3: BOLSA - 4 | B3: 4
A4: BOTELLAS - 5 | B4: 5
A5: CAJA - 6 | B5: 6
A6: CARTONES - 7 | B6: 7
A7: CILINDRO - 8 | B7: 8
A8: CONOS - 9 | B8: 9
A9: GRAMO - 10 | B9: 10
A10: JUEGO - 11 | B10: 11
A11: KILOGRAMO - 2 | B11: 2
A12: KILOMETRO - 12 | B12: 12
A13: KIT - 13 | B13: 13
... A21: UNIDADES - 1 | B21: 1

Sheet CATEGORIA
A1: NOMBRE | B1: CODIGO
A2: ABONOS - 2 | B2: 2
A3: ACCESORIOS - 3 | B3: 3
A4: ADHERENTE - 4 | B4: 4
A5: ALIMENTO DE AVES - 6 | B5: 6
A6: ALIMENTO DE GATOS - 7 | B6: 7
A7: ALIMENTO DE PERRO - 5 | B7: 5
A8: ANTIBIOTICOS - 8 | B8: 8
A9: ANTIPARASITARIOS - 9 | B9: 9
A10: FERTELIZANTE - 10 | B10: 10
A11: FUNGIDA - 12 | B11: 12
A12: HERBICIDA - 13 | B12: 13
A13: INSECTICIDAS - 14 | B13: 14
... A19: VITAMINAS - 18 | B19: 18

Sheet TIPO_ARTICULO
A1: NOMBRE | B1: CODIGO
A2: PRODUCTO - 1 | B2: 1
A3: SERVICIO - 2 | B3: 2

Sheet TIPO_IGV
A1: NOMBRE | B1: CODIGO
A2: BONIFICACION - 2 | B2: 2
A3: DOLAR - 3 | B3: 3
A4: Exonerado Operacin onerosa - 4 | B4: 4
A5: GRAVADO - 1 | B5: 1

Sheet PRODUCTOS
A1: ALMACEN | C1: MARCA | E1: UNIDAD | G1: CATEGORIA | I1: TIPO_ARTICULO | K1: TIPO_IGV | M1: NOMBRE PRODUCTO | N1: PRECIO COMPRA | O1: PRECIO VENTA | P1: PRECIO MAYOR | Q1: PRECIO ESPECIAL | R1: STOCK MÍNIMO | S1: STOCK | T1: CÓDIGO DE BARRAS
A2: ALMACEN CENTRAL - 1 | B2: =VLOOKUP(A2,ALMACEN!A2:B3,2,FALSE) -> 1 | C2: GENERICOS - 1 | D2: =VLOOKUP(C2,MARCA!A2:B2,2,FALSE) -> 1 | E2: CILINDRO - 8 | F2: =VLOOKUP(E2,UNIDAD!A2:B21,2,FALSE) -> 8 | G2: ALIMENTO DE GATOS - 7 | H2: =VLOOKUP(G2,CATEGORIA!A2:B19,2,FALSE) -> 7 | I2: PRODUCTO - 1 | J2: =VLOOKUP(I2,TIPO_ARTICULO!A2:B3,2,FALSE) -> 1 | K2: GRAVADO - 1 | L2: =VLOOKUP(K2,TIPO_IGV!A2:B5,2,FALSE) -> 1 | M2: PRODUCTO PRUEBA 2 | N2: 1 | O2: 1 | P2: 1 | Q2: 1 | R2: 1 | S2: 1 | T2: 12312
B3: =VLOOKUP(A3,ALMACEN!A2:B3,2,FALSE) -> #N/A | D3: =VLOOKUP(C3,MARCA!A2:B2,2,FALSE) -> #N/A | F3: =VLOOKUP(E3,UNIDAD!A2:B21,2,FALSE) -> #N/A | H3: =VLOOKUP(G3,CATEGORIA!A2:B19,2,FALSE) -> #N/A | J3: =VLOOKUP(I3,TIPO_ARTICULO!A2:B3,2,FALSE) -> #N/A | L3: =VLOOKUP(K3,TIPO_IGV!A2:B5,2,FALSE) -> #N/A
B4: =VLOOKUP(A4,ALMACEN!A2:B3,2,FALSE) -> #N/A | D4: =VLOOKUP(C4,MARCA!A2:B2,2,FALSE) -> #N/A | F4: =VLOOKUP(E4,UNIDAD!A2:B21,2,FALSE) -> #N/A | H4: =VLOOKUP(G4,CATEGORIA!A2:B19,2,FALSE) -> #N/A | J4: =VLOOKUP(I4,TIPO_ARTICULO!A2:B3,2,FALSE) -> #N/A | L4: =VLOOKUP(K4,TIPO_IGV!A2:B5,2,FALSE) -> #N/A
B5: =VLOOKUP(A5,ALMACEN!A2:B3,2,FALSE) -> #N/A | D5: =VLOOKUP(C5,MARCA!A2:B2,2,FALSE) -> #N/A | F5: =VLOOKUP(E5,UNIDAD!A2:B21,2,FALSE) -> #N/A | H5: =VLOOKUP(G5,CATEGORIA!A2:B19,2,FALSE) -> #N/A | J5: =VLOOKUP(I5,TIPO_ARTICULO!A2:B3,2,FALSE) -> #N/A | L5: =VLOOKUP(K5,TIPO_IGV!A2:B5,2,FALSE) -> #N/A
B6: =VLOOKUP(A6,ALMACEN!A2:B3,2,FALSE) -> #N/A | D6: =VLOOKUP(C6,MARCA!A2:B2,2,FALSE) -> #N/A | F6: =VLOOKUP(E6,UNIDAD!A2:B21,2,FALSE) -> #N/A | H6: =VLOOKUP(G6,CATEGORIA!A2:B19,2,FALSE) -> #N/A | J6: =VLOOKUP(I6,TIPO_ARTICULO!A2:B3,2,FALSE) -> #N/A | L6: =VLOOKUP(K6,TIPO_IGV!A2:B5,2,FALSE) -> #N/A
B7: =VLOOKUP(A7,ALMACEN!A2:B3,2,FALSE) -> #N/A | D7: =VLOOKUP(C7,MARCA!A2:B2,2,FALSE) -> #N/A | F7: =VLOOKUP(E7,UNIDAD!A2:B21,2,FALSE) -> #N/A | H7: =VLOOKUP(G7,CATEGORIA!A2:B19,2,FALSE) -> #N/A | J7: =VLOOKUP(I7,TIPO_ARTICULO!A2:B3,2,FALSE) -> #N/A | L7: =VLOOKUP(K7,TIPO_IGV!A2:B5,2,FALSE) -> #N/A
B8: =VLOOKUP(A8,ALMACEN!A2:B3,2,FALSE) -> #N/A | D8: =VLOOKUP(C8,MARCA!A2:B2,2,FALSE) -> #N/A | F8: =VLOOKUP(E8,UNIDAD!A2:B21,2,FALSE) -> #N/A | H8: =VLOOKUP(G8,CATEGORIA!A2:B19,2,FALSE) -> #N/A | J8: =VLOOKUP(I8,TIPO_ARTICULO!A2:B3,2,FALSE) -> #N/A | L8: =VLOOKUP(K8,TIPO_IGV!A2:B5,2,FALSE) -> #N/A
B9: =VLOOKUP(A9,ALMACEN!A2:B3,2,FALSE) -> #N/A | D9: =VLOOKUP(C9,MARCA!A2:B2,2,FALSE) -> #N/A | F9: =VLOOKUP(E9,UNIDAD!A2:B21,2,FALSE) -> #N/A | H9: =VLOOKUP(G9,CATEGORIA!A2:B19,2,FALSE) -> #N/A | J9: =VLOOKUP(I9,TIPO_ARTICULO!A2:B3,2,FALSE) -> #N/A | L9: =VLOOKUP(K9,TIPO_IGV!A2:B5,2,FALSE) -> #N/A
B10: =VLOOKUP(A10,ALMACEN!A2:B3,2,FALSE) -> #N/A | D10: =VLOOKUP(C10,MARCA!A2:B2,2,FALSE) -> #N/A | F10: =VLOOKUP(E10,UNIDAD!A2:B21,2,FALSE) -> #N/A | H10: =VLOOKUP(G10,CATEGORIA!A2:B19,2,FALSE) -> #N/A | J10: =VLOOKUP(I10,TIPO_ARTICULO!A2:B3,2,FALSE) -> #N/A | L10: =VLOOKUP(K10,TIPO_IGV!A2:B5,2,FALSE) -> #N/A
B11: =VLOOKUP(A11,ALMACEN!A2:B3,2,FALSE) -> #N/A | D11: =VLOOKUP(C11,MARCA!A2:B2,2,FALSE) -> #N/A | F11: =VLOOKUP(E11,UNIDAD!A2:B21,2,FALSE) -> #N/A | H11: =VLOOKUP(G11,CATEGORIA!A2:B19,2,FALSE) -> #N/A | J11: =VLOOKUP(I11,TIPO_ARTICULO!A2:B3,2,FALSE) -> #N/A | L11: =VLOOKUP(K11,TIPO_IGV!A2:B5,2,FALSE) -> #N/A
B12: =VLOOKUP(A12,ALMACEN!A2:B3,2,FALSE) -> #N/A | D12: =VLOOKUP(C12,MARCA!A2:B2,2,FALSE) -> #N/A | F12: =VLOOKUP(E12,UNIDAD!A2:B21,2,FALSE) -> #N/A | H12: =VLOOKUP(G12,CATEGORIA!A2:B19,2,FALSE) -> #N/A | J12: =VLOOKUP(I12,TIPO_ARTICULO!A2:B3,2,FALSE) -> #N/A | L12: =VLOOKUP(K12,TIPO_IGV!A2:B5,2,FALSE) -> #N/A
B13: =VLOOKUP(A13,ALMACEN!A2:B3,2,FALSE) -> #N/A | D13: =VLOOKUP(C13,MARCA!A2:B2,2,FALSE) -> #N/A | F13: =VLOOKUP(E13,UNIDAD!A2:B21,2,FALSE) -> #N/A | H13: =VLOOKUP(G13,CATEGORIA!A2:B19,2,FALSE) -> #N/A | J13: =VLOOKUP(I13,TIPO_ARTICULO!A2:B3,2,FALSE) -> #N/A | L13: =VLOOKUP(K13,TIPO_IGV!A2:B5,2,FALSE) -> #N/A
B14: =VLOOKUP(A14,ALMACEN!A2:B3,2,FALSE) -> #N/A | D14: =VLOOKUP(C14,MARCA!A2:B2,2,FALSE) -> #N/A | F14: =VLOOKUP(E14,UNIDAD!A2:B21,2,FALSE) -> #N/A | H14: =VLOOKUP(G14,CATEGORIA!A2:B19,2,FALSE) -> #N/A | J14: =VLOOKUP(I14,TIPO_ARTICULO!A2:B3,2,FALSE) -> #N/A | L14: =VLOOKUP(K14,TIPO_IGV!A2:B5,2,FALSE) -> #N/A
B15: =VLOOKUP(A15,ALMACEN!A2:B3,2,FALSE) -> #N/A | D15: =VLOOKUP(C15,MARCA!A2:B2,2,FALSE) -> #N/A | F15: =VLOOKUP(E15,UNIDAD!A2:B21,2,FALSE) -> #N/A | H15: =VLOOKUP(G15,CATEGORIA!A2:B19,2,FALSE) -> #N/A | J15: =VLOOKUP(I15,TIPO_ARTICULO!A2:B3,2,FALSE) -> #N/A | L15: =VLOOKUP(K15,TIPO_IGV!A2:B5,2,FALSE) -> #N/A
B16: =VLOOKUP(A16,ALMACEN!A2:B3,2,FALSE) -> #N/A | D16: =VLOOKUP(C16,MARCA!A2:B2,2,FALSE) -> #N/A | F16: =VLOOKUP(E16,UNIDAD!A2:B21,2,FALSE) -> #N/A | H16: =VLOOKUP(G16,CATEGORIA!A2:B19,2,FALSE) -> #N/A | J16: =VLOOKUP(I16,TIPO_ARTICULO!A2:B3,2,FALSE) -> #N/A | L16: =VLOOKUP(K16,TIPO_IGV!A2:B5,2,FALSE) -> #N/A
B17: =VLOOKUP(A17,ALMACEN!A2:B3,2,FALSE) -> #N/A | D17: =VLOOKUP(C17,MARCA!A2:B2,2,FALSE) -> #N/A | F17: =VLOOKUP(E17,UNIDAD!A2:B21,2,FALSE) -> #N/A | H17: =VLOOKUP(G17,CATEGORIA!A2:B19,2,FALSE) -> #N/A | J17: =VLOOKUP(I17,TIPO_ARTICULO!A2:B3,2,FALSE) -> #N/A | L17: =VLOOKUP(K17,TIPO_IGV!A2:B5,2,FALSE) -> #N/A
B18: =VLOOKUP(A18,ALMACEN!A2:B3,2,FALSE) -> #N/A | D18: =VLOOKUP(C18,MARCA!A2:B2,2,FALSE) -> #N/A | F18: =VLOOKUP(E18,UNIDAD!A2:B21,2,FALSE) -> #N/A | H18: =VLOOKUP(G18,CATEGORIA!A2:B19,2,FALSE) -> #N/A | J18: =VLOOKUP(I18,TIPO_ARTICULO!A2:B3,2,FALSE) -> #N/A | L18: =VLOOKUP(K18,TIPO_IGV!A2:B5,2,FALSE) -> #N/A
B19: =VLOOKUP(A19,ALMACEN!A2:B3,2,FALSE) -> #N/A | D19: =VLOOKUP(C19,MARCA!A2:B2,2,FALSE) -> #N/A | F19: =VLOOKUP(E19,UNIDAD!A2:B21,2,FALSE) -> #N/A | H19: =VLOOKUP(G19,CATEGORIA!A2:B19,2,FALSE) -> #N/A | J19: =VLOOKUP(I19,TIPO_ARTICULO!A2:B3,2,FALSE) -> #N/A | L19: =VLOOKUP(K19,TIPO_IGV!A2:B5,2,FALSE) -> #N/A
B20: =VLOOKUP(A20,ALMACEN!A2:B3,2,FALSE) -> #N/A | D20: =VLOOKUP(C20,MARCA!A2:B2,2,FALSE) -> #N/A | F20: =VLOOKUP(E20,UNIDAD!A2:B21,2,FALSE) -> #N/A | H20: =VLOOKUP(G20,CATEGORIA!A2:B19,2,FALSE) -> #N/A | J20: =VLOOKUP(I20,TIPO_ARTICULO!A2:B3,2,FALSE) -> #N/A | L20: =VLOOKUP(K20,TIPO_IGV!A2:B5,2,FALSE) -> #N/A
B21: =VLOOKUP(A21,ALMACEN!A2:B3,2,FALSE) -> #N/A | D21: =VLOOKUP(C21,MARCA!A2:B2,2,FALSE) -> #N/A | F21: =VLOOKUP(E21,UNIDAD!A2:B21,2,FALSE) -> #N/A | H21: =VLOOKUP(G21,CATEGORIA!A2:B19,2,FALSE) -> #N/A | J21: =VLOOKUP(I21,TIPO_ARTICULO!A2:B3,2,FALSE) -> #N/A | L21: =VLOOKUP(K21,TIPO_IGV!A2:B5,2,FALSE) -> #N/A
B22: =VLOOKUP(A22,ALMACEN!A2:B3,2,FALSE) -> #N/A | D22: =VLOOKUP(C22,MARCA!A2:B2,2,FALSE) -> #N/A | F22: =VLOOKUP(E22,UNIDAD!A2:B21,2,FALSE) -> #N/A | H22: =VLOOKUP(G22,CATEGORIA!A2:B19,2,FALSE) -> #N/A | J22: =VLOOKUP(I22,TIPO_ARTICULO!A2:B3,2,FALSE) -> #N/A | L22: =VLOOKUP(K22,TIPO_IGV!A2:B5,2,FALSE) -> #N/A
B23: =VLOOKUP(A23,ALMACEN!A2:B3,2,FALSE) -> #N/A | D23: =VLOOKUP(C23,MARCA!A2:B2,2,FALSE) -> #N/A | F23: =VLOOKUP(E23,UNIDAD!A2:B21,2,FALSE) -> #N/A | H23: =VLOOKUP(G23,CATEGORIA!A2:B19,2,FALSE) -> #N/A | J23: =VLOOKUP(I23,TIPO_ARTICULO!A2:B3,2,FALSE) -> #N/A | L23: =VLOOKUP(K23,TIPO_IGV!A2:B5,2,FALSE) -> #N/A
B24: =VLOOKUP(A24,ALMACEN!A2:B3,2,FALSE) -> #N/A | D24: =VLOOKUP(C24,MARCA!A2:B2,2,FALSE) -> #N/A | F24: =VLOOKUP(E24,UNIDAD!A2:B21,2,FALSE) -> #N/A | H24: =VLOOKUP(G24,CATEGORIA!A2:B19,2,FALSE) -> #N/A | J24: =VLOOKUP(I24,TIPO_ARTICULO!A2:B3,2,FALSE) -> #N/A | L24: =VLOOKUP(K24,TIPO_IGV!A2:B5,2,FALSE) -> #N/A
B25: =VLOOKUP(A25,ALMACEN!A2:B3,2,FALSE) -> #N/A | D25: =VLOOKUP(C25,MARCA!A2:B2,2,FALSE) -> #N/A | F25: =VLOOKUP(E25,UNIDAD!A2:B21,2,FALSE) -> #N/A | H25: =VLOOKUP(G25,CATEGORIA!A2:B19,2,FALSE) -> #N/A | J25: =VLOOKUP(I25,TIPO_ARTICULO!A2:B3,2,FALSE) -> #N/A | L25: =VLOOKUP(K25,TIPO_IGV!A2:B5,2,FALSE) -> #N/A
B26: =VLOOKUP(A26,ALMACEN!A2:B3,2,FALSE) -> #N/A | D26: =VLOOKUP(C26,MARCA!A2:B2,2,FALSE) -> #N/A | F26: =VLOOKUP(E26,UNIDAD!A2:B21,2,FALSE) -> #N/A | H26: =VLOOKUP(G26,CATEGORIA!A2:B19,2,FALSE) -> #N/A | J26: =VLOOKUP(I26,TIPO_ARTICULO!A2:B3,2,FALSE) -> #N/A | L26: =VLOOKUP(K26,TIPO_IGV!A2:B5,2,FALSE) -> #N/A
B27: =VLOOKUP(A27,ALMACEN!A2:B3,2,FALSE) -> #N/A | D27: =VLOOKUP(C27,MARCA!A2:B2,2,FALSE) -> #N/A | F27: =VLOOKUP(E27,UNIDAD!A2:B21,2,FALSE) -> #N/A | H27: =VLOOKUP(G27,CATEGORIA!A2:B19,2,FALSE) -> #N/A | J27: =VLOOKUP(I27,TIPO_ARTICULO!A2:B3,2,FALSE) -> #N/A | L27: =VLOOKUP(K27,TIPO_IGV!A2:B5,2,FALSE) -> #N/A
B28: =VLOOKUP(A28,ALMACEN!A2:B3,2,FALSE) -> #N/A | D28: =VLOOKUP(C28,MARCA!A2:B2,2,FALSE) -> #N/A | F28: =VLOOKUP(E28,UNIDAD!A2:B21,2,FALSE) -> #N/A | H28: =VLOOKUP(G28,CATEGORIA!A2:B19,2,FALSE) -> #N/A | J28: =VLOOKUP(I28,TIPO_ARTICULO!A2:B3,2,FALSE) -> #N/A | L28: =VLOOKUP(K28,TIPO_IGV!A2:B5,2,FALSE) -> #N/A
B29: =VLOOKUP(A29,ALMACEN!A2:B3,2,FALSE) -> #N/A | D29: =VLOOKUP(C29,MARCA!A2:B2,2,FALSE) -> #N/A | F29: =VLOOKUP(E29,UNIDAD!A2:B21,2,FALSE) -> #N/A | H29: =VLOOKUP(G29,CATEGORIA!A2:B19,2,FALSE) -> #N/A | J29: =VLOOKUP(I29,TIPO_ARTICULO!A2:B3,2,FALSE) -> #N/A | L29: =VLOOKUP(K29,TIPO_IGV!A2:B5,2,FALSE) -> #N/A
B30: =VLOOKUP(A30,ALMACEN!A2:B3,2,FALSE) -> #N/A | D30: =VLOOKUP(C30,MARCA!A2:B2,2,FALSE) -> #N/A | F30: =VLOOKUP(E30,UNIDAD!A2:B21,2,FALSE) -> #N/A | H30: =VLOOKUP(G30,CATEGORIA!A2:B19,2,FALSE) -> #N/A | J30: =VLOOKUP(I30,TIPO_ARTICULO!A2:B3,2,FALSE) -> #N/A | L30: =VLOOKUP(K30,TIPO_IGV!A2:B5,2,FALSE) -> #N/A
B31: =VLOOKUP(A31,ALMACEN!A2:B3,2,FALSE) -> #N/A | D31: =VLOOKUP(C31,MARCA!A2:B2,2,FALSE) -> #N/A | F31: =VLOOKUP(E31,UNIDAD!A2:B21,2,FALSE) -> #N/A | H31: =VLOOKUP(G31,CATEGORIA!A2:B19,2,FALSE) -> #N/A | J31: =VLOOKUP(I31,TIPO_ARTICULO!A2:B3,2,FALSE) -> #N/A | L31: =VLOOKUP(K31,TIPO_IGV!A2:B5,2,FALSE) -> #N/A
B32: =VLOOKUP(A32,ALMACEN!A2:B3,2,FALSE) -> #N/A | D32: =VLOOKUP(C32,MARCA!A2:B2,2,FALSE) -> #N/A | F32: =VLOOKUP(E32,UNIDAD!A2:B21,2,FALSE) -> #N/A | H32: =VLOOKUP(G32,CATEGORIA!A2:B19,2,FALSE) -> #N/A | J32: =VLOOKUP(I32,TIPO_ARTICULO!A2:B3,2,FALSE) -> #N/A | L32: =VLOOKUP(K32,TIPO_IGV!A2:B5,2,FALSE) -> #N/A
B33: =VLOOKUP(A33,ALMACEN!A2:B3,2,FALSE) -> #N/A | D33: =VLOOKUP(C33,MARCA!A2:B2,2,FALSE) -> #N/A | F33: =VLOOKUP(E33,UNIDAD!A2:B21,2,FALSE) -> #N/A | H33: =VLOOKUP(G33,CATEGORIA!A2:B19,2,FALSE) -> #N/A | J33: =VLOOKUP(I33,TIPO_ARTICULO!A2:B3,2,FALSE) -> #N/A | L33: =VLOOKUP(K33,TIPO_IGV!A2:B5,2,FALSE) -> #N/A
B34: =VLOOKUP(A34,ALMACEN!A2:B3,2,FALSE) -> #N/A | D34: =VLOOKUP(C34,MARCA!A2:B2,2,FALSE) -> #N/A | F34: =VLOOKUP(E34,UNIDAD!A2:B21,2,FALSE) -> #N/A | H34: =VLOOKUP(G34,CATEGORIA!A2:B19,2,FALSE) -> #N/A | J34: =VLOOKUP(I34,TIPO_ARTICULO!A2:B3,2,FALSE) -> #N/A | L34: =VLOOKUP(K34,TIPO_IGV!A2:B5,2,FALSE) -> #N/A
B35: =VLOOKUP(A35,ALMACEN!A2:B3,2,FALSE) -> #N/A | D35: =VLOOKUP(C35,MARCA!A2:B2,2,FALSE) -> #N/A | F35: =VLOOKUP(E35,UNIDAD!A2:B21,2,FALSE) -> #N/A | H35: =VLOOKUP(G35,CATEGORIA!A2:B19,2,FALSE) -> #N/A | J35: =VLOOKUP(I35,TIPO_ARTICULO!A2:B3,2,FALSE) -> #N/A | L35: =VLOOKUP(K35,TIPO_IGV!A2:B5,2,FALSE) -> #N/A
B36: =VLOOKUP(A36,ALMACEN!A2:B3,2,FALSE) -> #N/A | D36: =VLOOKUP(C36,MARCA!A2:B2,2,FALSE) -> #N/A | F36: =VLOOKUP(E36,UNIDAD!A2:B21,2,FALSE) -> #N/A | H36: =VLOOKUP(G36,CATEGORIA!A2:B19,2,FALSE) -> #N/A | J36: =VLOOKUP(I36,TIPO_ARTICULO!A2:B3,2,FALSE) -> #N/A | L36: =VLOOKUP(K36,TIPO_IGV!A2:B5,2,FALSE) -> #N/A
B37: =VLOOKUP(A37,ALMACEN!A2:B3,2,FALSE) -> #N/A | D37: =VLOOKUP(C37,MARCA!A2:B2,2,FALSE) -> #N/A | F37: =VLOOKUP(E37,UNIDAD!A2:B21,2,FALSE) -> #N/A | H37: =VLOOKUP(G37,CATEGORIA!A2:B19,2,FALSE) -> #N/A | J37: =VLOOKUP(I37,TIPO_ARTICULO!A2:B3,2,FALSE) -> #N/A | L37: =VLOOKUP(K37,TIPO_IGV!A2:B5,2,FALSE) -> #N/A
B38: =VLOOKUP(A38,ALMACEN!A2:B3,2,FALSE) -> #N/A | D38: =VLOOKUP(C38,MARCA!A2:B2,2,FALSE) -> #N/A | F38: =VLOOKUP(E38,UNIDAD!A2:B21,2,FALSE) -> #N/A | H38: =VLOOKUP(G38,CATEGORIA!A2:B19,2,FALSE) -> #N/A | J38: =VLOOKUP(I38,TIPO_ARTICULO!A2:B3,2,FALSE) -> #N/A | L38: =VLOOKUP(K38,TIPO_IGV!A2:B5,2,FALSE) -> #N/A
B39: =VLOOKUP(A39,ALMACEN!A2:B3,2,FALSE) -> #N/A | D39: =VLOOKUP(C39,MARCA!A2:B2,2,FALSE) -> #N/A | F39: =VLOOKUP(E39,UNIDAD!A2:B21,2,FALSE) -> #N/A | H39: =VLOOKUP(G39,CATEGORIA!A2:B19,2,FALSE) -> #N/A | J39: =VLOOKUP(I39,TIPO_ARTICULO!A2:B3,2,FALSE) -> #N/A | L39: =VLOOKUP(K39,TIPO_IGV!A2:B5,2,FALSE) -> #N/A
B40: =VLOOKUP(A40,ALMACEN!A2:B3,2,FALSE) -> #N/A | D40: =VLOOKUP(C40,MARCA!A2:B2,2,FALSE) -> #N/A | F40: =VLOOKUP(E40,UNIDAD!A2:B21,2,FALSE) -> #N/A | H40: =VLOOKUP(G40,CATEGORIA!A2:B19,2,FALSE) -> #N/A | J40: =VLOOKUP(I40,TIPO_ARTICULO!A2:B3,2,FALSE) -> #N/A | L40: =VLOOKUP(K40,TIPO_IGV!A2:B5,2,FALSE) -> #N/A
...
